  <joint name="base_fixed_joint" type="fixed">
    <parent link="base" />
    <child link="link_0" />
    <origin rpy="0.0 0.0 0.0" xyz="0.0 0.0 0.0" />
  </joint>

  <joint name="joint_1" type="revolute">
    <parent link="link_0" />
    <child link="link_1" />
    <origin rpy="0.000000 -0.000000 0.000003" xyz="0.000000 0.000000 0.145100" />
    <axis xyz="0 0 1" />
    <limit effort="157" lower="-4.71238898038469" upper="4.71238898038469" velocity="3.141592653589793" />
    <dynamics damping="0.0" friction="0.0" />
  </joint>

  <joint name="joint_2" type="revolute">
    <parent link="link_1" />
    <child link="link_2" />
    <origin rpy="-1.728326 -1.569466 0.157532" xyz="0.000027 -0.000038 0.000000" />
    <axis xyz="0 0 1" />
    <limit effort="157" lower="-3.141592653589793" upper="3.141592653589793" velocity="3.141592653589793" />
    <dynamics damping="0.0" friction="0.0" />
  </joint>

  <joint name="joint_3" type="revolute">
    <parent link="link_2" />
    <child link="link_3" />
    <origin rpy="0.000172 -0.001128 -0.006163" xyz="0.329003 0.000000 -0.000038" />
    <axis xyz="0 0 1" />
    <limit effort="157" lower="-2.705260340591211" upper="2.705260340591211" velocity="3.141592653589793" />
    <dynamics damping="0.0" friction="0.0" />
  </joint>

  <joint name="joint_4" type="revolute">
    <parent link="link_3" />
    <child link="link_4" />
    <origin rpy="-0.000864 -0.002089 1.573487" xyz="0.311594 0.000256 -0.122238" />
    <axis xyz="0 0 1" />
    <limit effort="43" lower="-3.141592653589793" upper="3.141592653589793" velocity="3.9269908169872414" />
    <dynamics damping="0.0" friction="0.0" />
  </joint>

  <joint name="joint_5" type="revolute">
    <parent link="link_4" />
    <child link="link_5" />
    <origin rpy="1.571867 0.001663 0.002692" xyz="0.000319 -0.106000 -0.000114" />
    <axis xyz="0 0 1" />
    <limit effort="43" lower="-3.141592653589793" upper="3.141592653589793" velocity="3.9269908169872414" />
    <dynamics damping="0.0" friction="0.0" />
  </joint>

  <joint name="joint_6" type="revolute">
    <parent link="link_5" />
    <child link="link_6" />
    <origin rpy="1.569650 -0.002913 -0.001662" xyz="-0.000192 -0.114382 0.000131" />
    <axis xyz="0 0 1" />
    <limit effort="43" lower="-4.71238898038469" upper="4.71238898038469" velocity="3.9269908169872414" />
    <dynamics damping="0.0" friction="0.0" />
  </joint>

  <joint name="flange_fixed_joint" type="fixed">
    <parent link="link_6" />
    <child link="flange" />
    <origin rpy="0.004135 0.001161 0.000005" xyz="-0.000032 0.000000 0.000000" />
  </joint>